<?xml version="1.0"?>
<robot name="nextore_system" xmlns:xacro="http://ros.org/wiki/xacro">

<!--========================================== Constants ============================================-->

    <xacro:property name="M_PI"   value="3.14159265359" />

<!--========================================== Materials ============================================-->

<material name="Neobotix/Black">
    <color rgba="0.0 0.0 0.0 1.0"/>
</material>

<material name="Neobotix/Blue">
    <color rgba="0.0 0.0 0.8 1.0"/>
</material>

<material name="Neobotix/Green">
    <color rgba="0.0 0.8 0.0 1.0"/>
</material>

<material name="Neobotix/Grey">
    <color rgba="0.7 0.7 0.7 1.0"/>
</material>

<material name="Neobotix/Grey2">
    <color rgba="0.9 0.9 0.9 1.0"/>
</material>

<material name="Neobotix/Red">
    <color rgba="0.8 0.0 0.0 1.0"/>
</material>

<material name="Neobotix/White">
    <color rgba="1.0 1.0 1.0 1.0"/>
</material>

<material name="Neobotix/Yellow">
    <color rgba="1.0 1.0 0 1"/>
</material>

<material name="Neobotix/Aluminum">
    <color rgba="0.5 0.5 0.5 1"/>
</material>

<!--==================================== Gazebo Link References =====================================-->

<gazebo reference="base_link">
    <gravity>true</gravity>
    <self_collide>false</self_collide>
    <material value="Gazebo/Grey"/>
</gazebo>

<gazebo reference="base_footprint">
    <gravity>true</gravity>
    <self_collide>false</self_collide>
    <material value="Gazebo/Grey"/>
</gazebo>

<!--========================================= Base Macro ============================================-->

<!--The root link base_link has an inertia specified in the URDF,
    but KDL does not support a root link with an inertia. As a
    workaround, you can add an extra base_footprint link to your URDF. -->
<link name="base_footprint" />

<link name="base_link">
    <visual>
        <geometry>
          <mesh filename="package://working/models/Truck/shed_with_crane_simplified.stl"/>
        </geometry>
        <origin xyz="0 0 0" rpy="0 0 0" />
    </visual>
    <collision>
        <geometry>
          <mesh filename="package://working/models/Truck/shed_with_crane_simplified.stl"/>
        </geometry>
        <origin xyz="0 0 0" rpy="0 0 0" />
    </collision>
    <inertial>
        <mass value="1000" />
        <origin xyz="0 0 0" rpy="0 0 0"/>
        <inertia ixx="48167" ixy="0.00" ixz="0.00"
                 iyx="0.00" iyy="48167" iyz="0.00"
                 izx="0.00" izy="0.00" izz="48167"/>
    </inertial>
    <static> true </static>
</link>

<joint name="base_footprint_joint" type="fixed">
   <parent link="base_footprint"/>
   <child  link="base_link"/>
   <origin xyz="0 0 0" rpy="0 0 0"/>
</joint>

<!--================================ 1st Gazebo Sick Laser References ===================================-->

<gazebo reference="3d_lidar_1">
    <material value="Gazebo/Black"/>
    <sensor name="3d_lidar_sensor_1" type="ray">
        <pose>0 0 0 0 0 0</pose>
        <visualize>false</visualize>
        <update_rate>20</update_rate>
        <ray>
            <scan>
                <horizontal>
                    <samples>361</samples>
                    <resolution>1</resolution>
                    <min_angle>-${M_PI}</min_angle>
                    <max_angle>${M_PI}</max_angle>
                </horizontal>
                <vertical>
                    <samples>25</samples>
                    <resolution>1</resolution>
                    <min_angle>${(90-19.2)*M_PI/180.0}</min_angle>
                    <max_angle>${90*M_PI/180.0}</max_angle>
                </vertical>
            </scan>
            <range>
                <min>0.10</min>
                <max>260.0</max>
                <resolution>0.02</resolution>
            </range>
            <noise>
                <type>gaussian</type>
                <mean>0.0</mean>
                <stddev>0.01</stddev>
            </noise>
        </ray>
        <plugin name="gazebo_ros_laser_controller" filename="libgazebo_ros_velodyne_laser.so">
            <topicName>lidar3D_1/scan</topicName>
            <frameName>3d_lidar_1</frameName>
            <organize_cloud>false</organize_cloud>
            <min_range>0.10</min_range>
            <max_range>260.0</max_range>
            <gaussianNoise>0.008</gaussianNoise>
          </plugin>
    </sensor>
</gazebo>


<!-- 6DOF joints and links -->
<!-- Prismatic joints -->
<!--on x axis-->

<joint name="lidar_1_pris1_joint" type="prismatic">
    <axis xyz="1 0 0"/>
    <origin rpy="-${100*M_PI/180} 0 0" xyz="1 -8.3 8"/>
    <parent link="base_footprint"/>
    <child link="lidar_1_link_1"/>
    <dynamics damping="100.0" friction="100.0"/>
    <limit effort="1000" velocity="3" lower="-20" upper="20" />
</joint>

<link name="lidar_1_link_1">
    <inertial>
        <mass value="1"/>
        <origin rpy="0 0 0" xyz="0 0 0"/>
        <inertia ixx="1.0" ixy="0" ixz="0" iyy="1.0" iyz="0" izz="1.0"/>
    </inertial>
    <visual>
        <origin rpy="0 0 0" xyz="0 0 0"/>
        <geometry>
            <box size="0.01 0.01 0.01" />
        </geometry>
        <material name="Neobotix/Black"/>
    </visual>
    <collision>
        <origin rpy="0 0 0" xyz="0 0 0"/>
        <geometry>
            <box size="0.001 0.001 0.001" />
        </geometry>
    </collision>
</link>


<!--on y axis-->

<joint name="lidar_1_pris2_joint" type="prismatic">
    <axis xyz="0 1 0"/>
    <origin rpy="0 0 0" xyz="0 0 0"/>
    <parent link="lidar_1_link_1"/>
    <child link="lidar_1_link_2"/>
    <dynamics damping="100.0" friction="100.0"/>
    <limit effort="1000" velocity="3" lower="-20" upper="20" />
</joint>

<link name="lidar_1_link_2">
    <inertial>
        <mass value="1"/>
        <origin rpy="0 0 0" xyz="0 0 0"/>
        <inertia ixx="1.0" ixy="0" ixz="0" iyy="1.0" iyz="0" izz="1.0"/>
    </inertial>
    <visual>
        <origin rpy="0 0 0" xyz="0 0 0"/>
        <geometry>
            <box size="0.01 0.01 0.01" />
        </geometry>
        <material name="Neobotix/Black"/>
    </visual>
    <collision>
        <origin rpy="0 0 0" xyz="0 0 0"/>
        <geometry>
            <box size="0.001 0.001 0.001" />
        </geometry>
    </collision>
</link>


<!--on z axis-->

<joint name="lidar_1_pris3_joint" type="prismatic">
    <axis xyz="0 0 1"/>
    <origin rpy="0 0 0" xyz="0 0 0"/>
    <parent link="lidar_1_link_2"/>
    <child link="lidar_1_link_3"/>
    <dynamics damping="100.0" friction="100.0"/>
    <limit effort="1000" velocity="3" lower="-20" upper="20" />
</joint>

<link name="lidar_1_link_3">
    <inertial>
        <mass value="1"/>
        <origin rpy="0 0 0" xyz="0 0 0"/>
        <inertia ixx="1.0" ixy="0" ixz="0" iyy="1.0" iyz="0" izz="1.0"/>
    </inertial>
    <visual>
        <origin rpy="0 0 0" xyz="0 0 0"/>
        <geometry>
            <box size="0.01 0.01 0.01" />
        </geometry>
        <material name="Neobotix/Black"/>
    </visual>
    <collision>
        <origin rpy="0 0 0" xyz="0 0 0"/>
        <geometry>
            <box size="0.001 0.001 0.001" />
        </geometry>
    </collision>
</link>



<!-- Revolute joints -->
<!--around x axis-->

<joint name="lidar_1_rev1_joint" type="revolute">
    <axis xyz="1 0 0"/>
    <origin rpy="0 0 0" xyz="0 0 0"/>
    <parent link="lidar_1_link_3"/>
    <child link="lidar_1_link_4"/>
    <dynamics damping="100.0" friction="100.0"/>
    <limit effort="1000" velocity="3" lower="-${M_PI}" upper="${M_PI}" />
</joint>

<link name="lidar_1_link_4">
    <inertial>
        <mass value="1"/>
        <origin rpy="0 0 0" xyz="0 0 0"/>
        <inertia ixx="1.0" ixy="0" ixz="0" iyy="1.0" iyz="0" izz="1.0"/>
    </inertial>
    <visual>
        <origin rpy="0 0 0" xyz="0 0 0"/>
        <geometry>
            <box size="0.01 0.01 0.01" />
        </geometry>
        <material name="Neobotix/Black"/>
    </visual>
    <collision>
        <origin rpy="0 0 0" xyz="0 0 0"/>
        <geometry>
            <box size="0.001 0.001 0.001" />
        </geometry>
    </collision>
</link>


<!--around y axis-->

<joint name="lidar_1_rev2_joint" type="revolute">
    <axis xyz="0 1 0"/>
    <origin rpy="0 0 0" xyz="0 0 0"/>
    <parent link="lidar_1_link_4"/>
    <child link="lidar_1_link_5"/>
    <dynamics damping="100.0" friction="100.0"/>
    <limit effort="1000" velocity="3" lower="-${M_PI}" upper="${M_PI}" />
</joint>

<link name="lidar_1_link_5">
    <inertial>
        <mass value="1"/>
        <origin rpy="0 0 0" xyz="0 0 0"/>
        <inertia ixx="1.0" ixy="0" ixz="0" iyy="1.0" iyz="0" izz="1.0"/>
    </inertial>
    <visual>
        <origin rpy="0 0 0" xyz="0 0 0"/>
        <geometry>
            <box size="0.01 0.01 0.01" />
        </geometry>
        <material name="Neobotix/Black"/>
    </visual>
    <collision>
        <origin rpy="0 0 0" xyz="0 0 0"/>
        <geometry>
            <box size="0.001 0.001 0.001" />
        </geometry>
    </collision>
</link>


<!--around z axis-->
<!--end-effector-->

<joint name="lidar_1_rev3_joint" type="revolute">
    <axis xyz="0 0 1"/>
    <origin rpy="0 0 0" xyz="0 0 0"/>
    <parent link="lidar_1_link_5"/>
    <child link="3d_lidar_1"/>
    <dynamics damping="100.0" friction="100.0"/>
    <limit effort="1000" velocity="3" lower="-${M_PI}" upper="${M_PI}" />
</joint>

<link name="3d_lidar_1" type="laser">
    <inertial>
        <mass value="1"/>
        <origin rpy="0 0 0" xyz="0 0 0"/>
        <inertia ixx="1.0" ixy="0" ixz="0" iyy="1.0" iyz="0" izz="1.0"/>
    </inertial>
    <visual>
        <origin rpy="0 0 0" xyz="0 0 0"/>
        <geometry>
            <cylinder length="0.45" radius="0.15"/>
        </geometry>
        <material name="Neobotix/Black"/>
    </visual>
    <collision>
        <origin rpy="0 0 0" xyz="0 0 0"/>
        <geometry>
            <cylinder length="0.1" radius="0.05"/>
        </geometry>
    </collision>
</link>


<!--================================ 2nd Gazebo Sick Laser References ===================================-->

<gazebo reference="3d_lidar_2">
    <material value="Gazebo/Black"/>
    <sensor name="3d_lidar_sensor_2" type="ray">
        <pose>0 0 0 0 0 0</pose>
        <visualize>false</visualize>
        <update_rate>20</update_rate>
        <ray>
            <scan>
                <horizontal>
                    <samples>361</samples>
                    <resolution>1</resolution>
                    <min_angle>-${M_PI}</min_angle>
                    <max_angle>${M_PI}</max_angle>
                </horizontal>
                <vertical>
                    <samples>25</samples>
                    <resolution>1</resolution>
                    <min_angle>${(90-19.2)*M_PI/180.0}</min_angle>
                    <max_angle>${90*M_PI/180.0}</max_angle>
                </vertical>
            </scan>
            <range>
                <min>0.10</min>
                <max>260.0</max>
                <resolution>0.02</resolution>
            </range>
            <noise>
                <type>gaussian</type>
                <mean>0.0</mean>
                <stddev>0.01</stddev>
            </noise>
        </ray>
        <plugin name="gazebo_ros_laser_controller" filename="libgazebo_ros_velodyne_laser.so">
            <topicName>lidar3D_2/scan</topicName>
            <frameName>3d_lidar_2</frameName>
            <organize_cloud>false</organize_cloud>
            <min_range>0.10</min_range>
            <max_range>260.0</max_range>
            <gaussianNoise>0.008</gaussianNoise>
          </plugin>
    </sensor>
</gazebo>


<!-- 6DOF joints and links -->
<!-- Prismatic joints -->
<!--on x axis-->

<joint name="lidar_2_pris1_joint" type="prismatic">
    <axis xyz="1 0 0"/>
    <origin rpy="${100*M_PI/180} 0 0" xyz="1 8.4 8"/>
    <parent link="base_footprint"/>
    <child link="lidar_2_link_1"/>
    <dynamics damping="100.0" friction="100.0"/>
    <limit effort="1000" velocity="3" lower="-20" upper="20" />
</joint>

<link name="lidar_2_link_1">
    <inertial>
        <mass value="1"/>
        <origin rpy="0 0 0" xyz="0 0 0"/>
        <inertia ixx="1.0" ixy="0" ixz="0" iyy="1.0" iyz="0" izz="1.0"/>
    </inertial>
    <visual>
        <origin rpy="0 0 0" xyz="0 0 0"/>
        <geometry>
            <box size="0.01 0.01 0.01" />
        </geometry>
        <material name="Neobotix/Black"/>
    </visual>
    <collision>
        <origin rpy="0 0 0" xyz="0 0 0"/>
        <geometry>
            <box size="0.001 0.001 0.001" />
        </geometry>
    </collision>
</link>


<!--on y axis-->

<joint name="lidar_2_pris2_joint" type="prismatic">
    <axis xyz="0 1 0"/>
    <origin rpy="0 0 0" xyz="0 0 0"/>
    <parent link="lidar_2_link_1"/>
    <child link="lidar_2_link_2"/>
    <dynamics damping="100.0" friction="100.0"/>
    <limit effort="1000" velocity="3" lower="-20" upper="20" />
</joint>

<link name="lidar_2_link_2">
    <inertial>
        <mass value="1"/>
        <origin rpy="0 0 0" xyz="0 0 0"/>
        <inertia ixx="1.0" ixy="0" ixz="0" iyy="1.0" iyz="0" izz="1.0"/>
    </inertial>
    <visual>
        <origin rpy="0 0 0" xyz="0 0 0"/>
        <geometry>
            <box size="0.01 0.01 0.01" />
        </geometry>
        <material name="Neobotix/Black"/>
    </visual>
    <collision>
        <origin rpy="0 0 0" xyz="0 0 0"/>
        <geometry>
            <box size="0.001 0.001 0.001" />
        </geometry>
    </collision>
</link>


<!--on z axis-->

<joint name="lidar_2_pris3_joint" type="prismatic">
    <axis xyz="0 0 1"/>
    <origin rpy="0 0 0" xyz="0 0 0"/>
    <parent link="lidar_2_link_2"/>
    <child link="lidar_2_link_3"/>
    <dynamics damping="100.0" friction="100.0"/>
    <limit effort="1000" velocity="3" lower="-20" upper="20" />
</joint>

<link name="lidar_2_link_3">
    <inertial>
        <mass value="1"/>
        <origin rpy="0 0 0" xyz="0 0 0"/>
        <inertia ixx="1.0" ixy="0" ixz="0" iyy="1.0" iyz="0" izz="1.0"/>
    </inertial>
    <visual>
        <origin rpy="0 0 0" xyz="0 0 0"/>
        <geometry>
            <box size="0.01 0.01 0.01" />
        </geometry>
        <material name="Neobotix/Black"/>
    </visual>
    <collision>
        <origin rpy="0 0 0" xyz="0 0 0"/>
        <geometry>
            <box size="0.001 0.001 0.001" />
        </geometry>
    </collision>
</link>



<!-- Revolute joints -->
<!--around x axis-->

<joint name="lidar_2_rev1_joint" type="revolute">
    <axis xyz="1 0 0"/>
    <origin rpy="0 0 0" xyz="0 0 0"/>
    <parent link="lidar_2_link_3"/>
    <child link="lidar_2_link_4"/>
    <dynamics damping="100.0" friction="100.0"/>
    <limit effort="1000" velocity="3" lower="-${M_PI}" upper="${M_PI}" />
</joint>

<link name="lidar_2_link_4">
    <inertial>
        <mass value="1"/>
        <origin rpy="0 0 0" xyz="0 0 0"/>
        <inertia ixx="1.0" ixy="0" ixz="0" iyy="1.0" iyz="0" izz="1.0"/>
    </inertial>
    <visual>
        <origin rpy="0 0 0" xyz="0 0 0"/>
        <geometry>
            <box size="0.01 0.01 0.01" />
        </geometry>
        <material name="Neobotix/Black"/>
    </visual>
    <collision>
        <origin rpy="0 0 0" xyz="0 0 0"/>
        <geometry>
            <box size="0.001 0.001 0.001" />
        </geometry>
    </collision>
</link>


<!--around y axis-->

<joint name="lidar_2_rev2_joint" type="revolute">
    <axis xyz="0 1 0"/>
    <origin rpy="0 0 0" xyz="0 0 0"/>
    <parent link="lidar_2_link_4"/>
    <child link="lidar_2_link_5"/>
    <dynamics damping="100.0" friction="100.0"/>
    <limit effort="1000" velocity="3" lower="-${M_PI}" upper="${M_PI}" />
</joint>

<link name="lidar_2_link_5">
    <inertial>
        <mass value="1"/>
        <origin rpy="0 0 0" xyz="0 0 0"/>
        <inertia ixx="1.0" ixy="0" ixz="0" iyy="1.0" iyz="0" izz="1.0"/>
    </inertial>
    <visual>
        <origin rpy="0 0 0" xyz="0 0 0"/>
        <geometry>
            <box size="0.01 0.01 0.01" />
        </geometry>
        <material name="Neobotix/Black"/>
    </visual>
    <collision>
        <origin rpy="0 0 0" xyz="0 0 0"/>
        <geometry>
            <box size="0.001 0.001 0.001" />
        </geometry>
    </collision>
</link>


<!--around z axis-->
<!--end-effector-->

<joint name="lidar_2_rev3_joint" type="revolute">
    <axis xyz="0 0 1"/>
    <origin rpy="0 0 0" xyz="0 0 0"/>
    <parent link="lidar_2_link_5"/>
    <child link="3d_lidar_2"/>
    <dynamics damping="100.0" friction="100.0"/>
    <limit effort="1000" velocity="3" lower="-${M_PI}" upper="${M_PI}" />
</joint>

<link name="3d_lidar_2" type="laser">
    <inertial>
        <mass value="1"/>
        <origin rpy="0 0 0" xyz="0 0 0"/>
        <inertia ixx="1.0" ixy="0" ixz="0" iyy="1.0" iyz="0" izz="1.0"/>
    </inertial>
    <visual>
        <origin rpy="0 0 0" xyz="0 0 0"/>
        <geometry>
            <cylinder length="0.45" radius="0.15"/>
        </geometry>
        <material name="Neobotix/Black"/>
    </visual>
    <collision>
        <origin rpy="0 0 0" xyz="0 0 0"/>
        <geometry>
            <cylinder length="0.1" radius="0.05"/>
        </geometry>
    </collision>
</link>

<!--================================= Big truck - Hitachi truck ===================================-->

<joint name="Hitachi_truck_joint" type="prismatic">
    <axis xyz="1 0 0"/>
    <origin rpy="0 0 0" xyz="-20 0 0"/>
    <parent link="base_footprint"/>
    <child link="Hitachi_truck"/>
    <dynamics damping="100.0" friction="100.0"/>
    <limit effort="10000" velocity="4" lower="-20" upper="20" />
</joint>

<link name="Hitachi_truck">
    <visual>
        <geometry>
          <mesh filename="package://working/models/Truck/Hitachi_EH4000AC_truck_with_load_simplified.stl"/>
        </geometry>
        <origin xyz="0 0 0" rpy="0 0 0" />
    </visual>
    <collision>
        <geometry>
          <mesh filename="package://working/models/Truck/Hitachi_EH4000AC_truck_with_load_simplified.stl"/>
        </geometry>
        <origin xyz="0 0 0" rpy="0 0 0" />
    </collision>
    <inertial>
        <mass value="1000" />
        <origin xyz="0 0 0" rpy="0 0 0"/>
        <inertia ixx="48167" ixy="0.00" ixz="0.00"
                 iyx="0.00" iyy="48167" iyz="0.00"
                 izx="0.00" izy="0.00" izz="48167"/>
    </inertial>
</link>

<!--============================== Small truck - Caterpillar truck ================================-->

<joint name="Cat_truck_joint" type="prismatic">
    <axis xyz="1 0 0"/>
    <origin rpy="0 0 0" xyz="0 0 0"/>
    <parent link="base_footprint"/>
    <child link="Cat_truck"/>
    <dynamics damping="100.0" friction="100.0"/>
    <limit effort="10000" velocity="4" lower="-20" upper="20" />
</joint>

<link name="Cat_truck">
    <visual>
        <geometry>
          <mesh filename="package://working/models/Truck/Cat_785C_truck_with_load_simplified.stl"/>
        </geometry>
        <origin xyz="0 0 0" rpy="0 0 0" />
    </visual>
    <collision>
        <geometry>
          <mesh filename="package://working/models/Truck/Cat_785C_truck_with_load_simplified.stl"/>
        </geometry>
        <origin xyz="0 0 0" rpy="0 0 0" />
    </collision>
    <inertial>
        <mass value="1000" />
        <origin xyz="0 0 0" rpy="0 0 0"/>
        <inertia ixx="48167" ixy="0.00" ixz="0.00"
                 iyx="0.00" iyy="48167" iyz="0.00"
                 izx="0.00" izy="0.00" izz="48167"/>
    </inertial>
</link>




<!--================================ ROS control part ==================================-->
<!--plugin-->
  <gazebo>
    <plugin name="gazebo_ros_control" filename="libgazebo_ros_control.so">
      <robotNamespace>/nextore_system</robotNamespace>
    </plugin>
  </gazebo>

<!--lidar1-->
  <transmission name="lidar_1_tran_1">
    <type>transmission_interface/SimpleTransmission</type>
    <joint name="lidar_1_pris1_joint">
      <hardwareInterface>hardware_interface/EffortJointInterface</hardwareInterface>
    </joint>
    <actuator name="lidar_1_pris1_motor">
      <hardwareInterface>hardware_interface/EffortJointInterface</hardwareInterface>
      <mechanicalReduction>1</mechanicalReduction>
    </actuator>
  </transmission>

  <transmission name="lidar_1_tran_2">
    <type>transmission_interface/SimpleTransmission</type>
    <joint name="lidar_1_pris2_joint">
      <hardwareInterface>hardware_interface/EffortJointInterface</hardwareInterface>
    </joint>
    <actuator name="lidar_1_pris2_motor">
      <hardwareInterface>hardware_interface/EffortJointInterface</hardwareInterface>
      <mechanicalReduction>1</mechanicalReduction>
    </actuator>
  </transmission>

  <transmission name="lidar_1_tran_3">
    <type>transmission_interface/SimpleTransmission</type>
    <joint name="lidar_1_pris3_joint">
      <hardwareInterface>hardware_interface/EffortJointInterface</hardwareInterface>
    </joint>
    <actuator name="lidar_1_pris3_motor">
      <hardwareInterface>hardware_interface/EffortJointInterface</hardwareInterface>
      <mechanicalReduction>1</mechanicalReduction>
    </actuator>
  </transmission>

  <transmission name="lidar_1_tran_4">
    <type>transmission_interface/SimpleTransmission</type>
    <joint name="lidar_1_rev1_joint">
      <hardwareInterface>hardware_interface/EffortJointInterface</hardwareInterface>
    </joint>
    <actuator name="lidar_1_rev1_motor">
      <hardwareInterface>hardware_interface/EffortJointInterface</hardwareInterface>
      <mechanicalReduction>1</mechanicalReduction>
    </actuator>
  </transmission>

  <transmission name="lidar_1_tran_5">
    <type>transmission_interface/SimpleTransmission</type>
    <joint name="lidar_1_rev2_joint">
      <hardwareInterface>hardware_interface/EffortJointInterface</hardwareInterface>
    </joint>
    <actuator name="lidar_1_rev2_motor">
      <hardwareInterface>hardware_interface/EffortJointInterface</hardwareInterface>
      <mechanicalReduction>1</mechanicalReduction>
    </actuator>
  </transmission>

  <transmission name="lidar_1_tran_6">
    <type>transmission_interface/SimpleTransmission</type>
    <joint name="lidar_1_rev3_joint">
      <hardwareInterface>hardware_interface/EffortJointInterface</hardwareInterface>
    </joint>
    <actuator name="lidar_1_rev3_motor">
      <hardwareInterface>hardware_interface/EffortJointInterface</hardwareInterface>
      <mechanicalReduction>1</mechanicalReduction>
    </actuator>
  </transmission>

<!--lidar2-->
  <transmission name="lidar_2_tran_1">
    <type>transmission_interface/SimpleTransmission</type>
    <joint name="lidar_2_pris1_joint">
      <hardwareInterface>hardware_interface/EffortJointInterface</hardwareInterface>
    </joint>
    <actuator name="lidar_2_pris1_motor">
      <hardwareInterface>hardware_interface/EffortJointInterface</hardwareInterface>
      <mechanicalReduction>1</mechanicalReduction>
    </actuator>
  </transmission>

  <transmission name="lidar_2_tran_2">
    <type>transmission_interface/SimpleTransmission</type>
    <joint name="lidar_2_pris2_joint">
      <hardwareInterface>hardware_interface/EffortJointInterface</hardwareInterface>
    </joint>
    <actuator name="lidar_2_pris2_motor">
      <hardwareInterface>hardware_interface/EffortJointInterface</hardwareInterface>
      <mechanicalReduction>1</mechanicalReduction>
    </actuator>
  </transmission>

  <transmission name="lidar_2_tran_3">
    <type>transmission_interface/SimpleTransmission</type>
    <joint name="lidar_2_pris3_joint">
      <hardwareInterface>hardware_interface/EffortJointInterface</hardwareInterface>
    </joint>
    <actuator name="lidar_2_pris3_motor">
      <hardwareInterface>hardware_interface/EffortJointInterface</hardwareInterface>
      <mechanicalReduction>1</mechanicalReduction>
    </actuator>
  </transmission>

  <transmission name="lidar_2_tran_4">
    <type>transmission_interface/SimpleTransmission</type>
    <joint name="lidar_2_rev1_joint">
      <hardwareInterface>hardware_interface/EffortJointInterface</hardwareInterface>
    </joint>
    <actuator name="lidar_2_rev1_motor">
      <hardwareInterface>hardware_interface/EffortJointInterface</hardwareInterface>
      <mechanicalReduction>1</mechanicalReduction>
    </actuator>
  </transmission>

  <transmission name="lidar_2_tran_5">
    <type>transmission_interface/SimpleTransmission</type>
    <joint name="lidar_2_rev2_joint">
      <hardwareInterface>hardware_interface/EffortJointInterface</hardwareInterface>
    </joint>
    <actuator name="lidar_2_rev2_motor">
      <hardwareInterface>hardware_interface/EffortJointInterface</hardwareInterface>
      <mechanicalReduction>1</mechanicalReduction>
    </actuator>
  </transmission>

  <transmission name="lidar_2_tran_6">
    <type>transmission_interface/SimpleTransmission</type>
    <joint name="lidar_2_rev3_joint">
      <hardwareInterface>hardware_interface/EffortJointInterface</hardwareInterface>
    </joint>
    <actuator name="lidar_2_rev3_motor">
      <hardwareInterface>hardware_interface/EffortJointInterface</hardwareInterface>
      <mechanicalReduction>1</mechanicalReduction>
    </actuator>
  </transmission>

<!--trucks-->
  <transmission name="Hitachi_truck_tran">
    <type>transmission_interface/SimpleTransmission</type>
    <joint name="Hitachi_truck_joint">
      <hardwareInterface>hardware_interface/EffortJointInterface</hardwareInterface>
    </joint>
    <actuator name="Hitachi_truck_motor">
      <hardwareInterface>hardware_interface/EffortJointInterface</hardwareInterface>
      <mechanicalReduction>1</mechanicalReduction>
    </actuator>
  </transmission>

  <transmission name="Cat_truck_tran">
    <type>transmission_interface/SimpleTransmission</type>
    <joint name="Cat_truck_joint">
      <hardwareInterface>hardware_interface/EffortJointInterface</hardwareInterface>
    </joint>
    <actuator name="Cat_truck_motor">
      <hardwareInterface>hardware_interface/EffortJointInterface</hardwareInterface>
      <mechanicalReduction>1</mechanicalReduction>
    </actuator>
  </transmission>


</robot>
